Workbook

Sheet Executive Summary
B2: Indian Overseas Migration Analytics
B3: Executive Summary | Coverage: 2000-2024 | 7 Destination Countries
B5: Total Records | E5: Countries Covered | H5: Latest Year (Migrant Stock Data) | K5: Total Migrants Tracked, 2024 | N5: India GDP 2024 ($B) | Q5: Remittances 2024 ($B)
B6: =COUNTA('Migration Data'!A2:A183) -> 182 | E6: =SUMPRODUCT(1/COUNTIF('Migration Data'!B2:B183,'Migration Data'!B2:B183)) -> 7 | H6: =_xlfn.MAXIFS('Migration Data'!A2:A183,'Migration Data'!I2:I183,"<>") -> 2024 | K6: =SUMIFS('Migration Data'!I2:I183,'Migration Data'!A2:A183,2024) -> 10266000 | N6: =AVERAGEIFS('Migration Data'!D2:D183,'Migration Data'!A2:A183,2024) -> 3910 | Q6: =AVERAGEIFS('Migration Data'!F2:F183,'Migration Data'!A2:A183,2024) -> 137.67
B9: Headline Takeaways
B10: - UAE (3.25M) and USA (3.17M) are the largest tracked Indian migrant destinations as of 2024.
B11: - Canada is the fastest-growing corridor: +490% since 2000 (217K -> 1.28M).
B12: - UK growth lagged all tracked countries: only +70% since 2000, likely tied to post-Brexit visa tightening.
B13: - Remittances to India grew ~10.7x (2000-2024), tracking India's GDP (r=0.98) far more than migrant headcount.
B14: - India's GDP grew 8.3x over the same period with no corresponding slowdown in emigration.
B15: - Workforce/student composition data is too sparse (2 of 182 records) to support a general trend claim.
B17: Note: migrant-stock figures are recorded only in benchmark years (2000, 2005/2010, 2015, 2020, 2024). GDP, unemployment, and remittances are India-wide national figures repeated across countries, not country-specific. See 'Data Quality Report' tab for full detail.
B20: Chart Data (helper table - formulas pull from Migration Data)
B21: Country | C21: Migrants (2024)
B22: Australia | C22: =SUMIFS('Migration Data'!I2:I183,'Migration Data'!A2:A183,2024,'Migration Data'!B2:B183,"Australia") -> 916000
B23: Canada | C23: =SUMIFS('Migration Data'!I2:I183,'Migration Data'!A2:A183,2024,'Migration Data'!B2:B183,"Canada") -> 1280000
B24: Germany | C24: =SUMIFS('Migration Data'!I2:I183,'Migration Data'!A2:A183,2024,'Migration Data'!B2:B183,"Germany") -> 285000
B25: Singapore | C25: =SUMIFS('Migration Data'!I2:I183,'Migration Data'!A2:A183,2024,'Migration Data'!B2:B183,"Singapore") -> 395000
B26: UAE | C26: =SUMIFS('Migration Data'!I2:I183,'Migration Data'!A2:A183,2024,'Migration Data'!B2:B183,"UAE") -> 3250000
B27: UK | C27: =SUMIFS('Migration Data'!I2:I183,'Migration Data'!A2:A183,2024,'Migration Data'!B2:B183,"UK") -> 970000
B28: USA | C28: =SUMIFS('Migration Data'!I2:I183,'Migration Data'!A2:A183,2024,'Migration Data'!B2:B183,"USA") -> 3170000
B31: Year | C31: India GDP ($B) | D31: Remittances ($B)
B32: 2000 | C32: =AVERAGEIFS('Migration Data'!D2:D183,'Migration Data'!A2:A183,2000) -> 468.4 | D32: =AVERAGEIFS('Migration Data'!F2:F183,'Migration Data'!A2:A183,2000) -> 12.88
B33: 2001 | C33: =AVERAGEIFS('Migration Data'!D2:D183,'Migration Data'!A2:A183,2001) -> 485.44 | D33: =AVERAGEIFS('Migration Data'!F2:F183,'Migration Data'!A2:A183,2001) -> 14.27
B34: 2002 | C34: =AVERAGEIFS('Migration Data'!D2:D183,'Migration Data'!A2:A183,2002) -> 514.94 | D34: =AVERAGEIFS('Migration Data'!F2:F183,'Migration Data'!A2:A183,2002) -> 15.74
B35: 2003 | C35: =AVERAGEIFS('Migration Data'!D2:D183,'Migration Data'!A2:A183,2003) -> 607.7 | D35: =AVERAGEIFS('Migration Data'!F2:F183,'Migration Data'!A2:A183,2003) -> 21
B36: 2004 | C36: =AVERAGEIFS('Migration Data'!D2:D183,'Migration Data'!A2:A183,2004) -> 709.15 | D36: =AVERAGEIFS('Migration Data'!F2:F183,'Migration Data'!A2:A183,2004) -> 18.75
B37: 2005 | C37: =AVERAGEIFS('Migration Data'!D2:D183,'Migration Data'!A2:A183,2005) -> 820.38 | D37: =AVERAGEIFS('Migration Data'!F2:F183,'Migration Data'!A2:A183,2005) -> 22.13
B38: 2006 | C38: =AVERAGEIFS('Migration Data'!D2:D183,'Migration Data'!A2:A183,2006) -> 940.26 | D38: =AVERAGEIFS('Migration Data'!F2:F183,'Migration Data'!A2:A183,2006) -> 28.33
B39: 2007 | C39: =AVERAGEIFS('Migration Data'!D2:D183,'Migration Data'!A2:A183,2007) -> 1217 | D39: =AVERAGEIFS('Migration Data'!F2:F183,'Migration Data'!A2:A183,2007) -> 37.22
B40: 2008 | C40: =AVERAGEIFS('Migration Data'!D2:D183,'Migration Data'!A2:A183,2008) -> 1199 | D40: =AVERAGEIFS('Migration Data'!F2:F183,'Migration Data'!A2:A183,2008) -> 49.98
B41: 2009 | C41: =AVERAGEIFS('Migration Data'!D2:D183,'Migration Data'!A2:A183,2009) -> 1342 | D41: =AVERAGEIFS('Migration Data'!F2:F183,'Migration Data'!A2:A183,2009) -> 49.2
B42: 2010 | C42: =AVERAGEIFS('Migration Data'!D2:D183,'Migration Data'!A2:A183,2010) -> 1676 | D42: =AVERAGEIFS('Migration Data'!F2:F183,'Migration Data'!A2:A183,2010) -> 53.48
B43: 2011 | C43: =AVERAGEIFS('Migration Data'!D2:D183,'Migration Data'!A2:A183,2011) -> 1823 | D43: =AVERAGEIFS('Migration Data'!F2:F183,'Migration Data'!A2:A183,2011) -> 62.5
B44: 2012 | C44: =AVERAGEIFS('Migration Data'!D2:D183,'Migration Data'!A2:A183,2012) -> 1828 | D44: =AVERAGEIFS('Migration Data'!F2:F183,'Migration Data'!A2:A183,2012) -> 68.82
B45: 2013 | C45: =AVERAGEIFS('Migration Data'!D2:D183,'Migration Data'!A2:A183,2013) -> 1857 | D45: =AVERAGEIFS('Migration Data'!F2:F183,'Migration Data'!A2:A183,2013) -> 69.97
B46: 2014 | C46: =AVERAGEIFS('Migration Data'!D2:D183,'Migration Data'!A2:A183,2014) -> 2039 | D46: =AVERAGEIFS('Migration Data'!F2:F183,'Migration Data'!A2:A183,2014) -> 70.39
B47: 2015 | C47: =AVERAGEIFS('Migration Data'!D2:D183,'Migration Data'!A2:A183,2015) -> 2104 | D47: =AVERAGEIFS('Migration Data'!F2:F183,'Migration Data'!A2:A183,2015) -> 68.91
B48: 2016 | C48: =AVERAGEIFS('Migration Data'!D2:D183,'Migration Data'!A2:A183,2016) -> 2295 | D48: =AVERAGEIFS('Migration Data'!F2:F183,'Migration Data'!A2:A183,2016) -> 62.74
B49: 2017 | C49: =AVERAGEIFS('Migration Data'!D2:D183,'Migration Data'!A2:A183,2017) -> 2651 | D49: =AVERAGEIFS('Migration Data'!F2:F183,'Migration Data'!A2:A183,2017) -> 68.97
...

Sheet Migration Data
A1: Year | B1: Destination Country | C1: Region | D1: GDP India USD Billion | E1: Permanent Migrants | F1: Remittance USD Billion | G1: Students | H1: Temporary Workers | I1: Total Indian Migrants | J1: Unemployment India | K1: Destination Country Full | L1: Migrant YoY Growth Pct | M1: Temporary Worker Share Pct | N1: Student Share Pct | O1: Remittance per Migrant USD Th | P1: Migrant 3yr Moving Avg | Q1: High Migration Flag | R1: India Unemployment Category
A2: 2000 | B2: Australia | C2: Oceania | D2: 468.4 | F2: 12.88 | I2: 173000 | J2: 7.62 | K2: Australia | O2: 74.450867 | P2: 173000 | Q2: Normal | R2: Moderate (6-8%)
A3: 2001 | B3: Australia | C3: Oceania | D3: 485.44 | F3: 14.27 | J3: 7.61 | K3: Australia | P3: 173000 | Q3: Normal | R3: Moderate (6-8%)
A4: 2002 | B4: Australia | C4: Oceania | D4: 514.94 | F4: 15.74 | J4: 7.68 | K4: Australia | P4: 173000 | Q4: Normal | R4: Moderate (6-8%)
A5: 2003 | B5: Australia | C5: Oceania | D5: 607.7 | F5: 21 | J5: 7.63 | K5: Australia | Q5: Normal | R5: Moderate (6-8%)
A6: 2004 | B6: Australia | C6: Oceania | D6: 709.15 | F6: 18.75 | J6: 7.6 | K6: Australia | Q6: Normal | R6: Moderate (6-8%)
A7: 2005 | B7: Australia | C7: Oceania | D7: 820.38 | F7: 22.13 | J7: 7.55 | K7: Australia | Q7: Normal | R7: Moderate (6-8%)
A8: 2006 | B8: Australia | C8: Oceania | D8: 940.26 | F8: 28.33 | J8: 7.55 | K8: Australia | Q8: Normal | R8: Moderate (6-8%)
A9: 2007 | B9: Australia | C9: Oceania | D9: 1217 | F9: 37.22 | J9: 7.56 | K9: Australia | Q9: Normal | R9: Moderate (6-8%)
A10: 2008 | B10: Australia | C10: Oceania | D10: 1199 | F10: 49.98 | J10: 7.63 | K10: Australia | Q10: Normal | R10: Moderate (6-8%)
A11: 2009 | B11: Australia | C11: Oceania | D11: 1342 | F11: 49.2 | J11: 7.64 | K11: Australia | Q11: Normal | R11: Moderate (6-8%)
A12: 2010 | B12: Australia | C12: Oceania | D12: 1676 | E12: 17000 | F12: 53.48 | I12: 330000 | J12: 7.63 | K12: Australia | O12: 162.06061 | P12: 330000 | Q12: Normal | R12: Moderate (6-8%)
A13: 2011 | B13: Australia | C13: Oceania | D13: 1823 | F13: 62.5 | J13: 7.61 | K13: Australia | P13: 330000 | Q13: Normal | R13: Moderate (6-8%)
A14: 2012 | B14: Australia | C14: Oceania | D14: 1828 | F14: 68.82 | J14: 7.64 | K14: Australia | P14: 330000 | Q14: Normal | R14: Moderate (6-8%)
A15: 2013 | B15: Australia | C15: Oceania | D15: 1857 | F15: 69.97 | J15: 7.68 | K15: Australia | Q15: Normal | R15: Moderate (6-8%)
A16: 2014 | B16: Australia | C16: Oceania | D16: 2039 | F16: 70.39 | J16: 7.66 | K16: Australia | Q16: Normal | R16: Moderate (6-8%)
A17: 2015 | B17: Australia | C17: Oceania | D17: 2104 | F17: 68.91 | I17: 448000 | J17: 7.63 | K17: Australia | O17: 153.81696 | P17: 448000 | Q17: Normal | R17: Moderate (6-8%)
A18: 2016 | B18: Australia | C18: Oceania | D18: 2295 | F18: 62.74 | J18: 7.61 | K18: Australia | P18: 448000 | Q18: Normal | R18: Moderate (6-8%)
A19: 2017 | B19: Australia | C19: Oceania | D19: 2651 | E19: 33310 | F19: 68.97 | G19: 49469 | H19: 16124 | J19: 7.63 | K19: Australia | P19: 448000 | Q19: Normal | R19: Moderate (6-8%)
A20: 2018 | B20: Australia | C20: Oceania | D20: 2703 | E20: 33611 | F20: 78.79 | G20: 66449 | H20: 22357 | J20: 7.65 | K20: Australia | Q20: Normal | R20: Moderate (6-8%)
A21: 2019 | B21: Australia | C21: Oceania | D21: 2836 | E21: 25698 | F21: 83.33 | G21: 55560 | H21: 13434 | J21: 6.51 | K21: Australia | Q21: Normal | R21: Moderate (6-8%)
A22: 2020 | B22: Australia | C22: Oceania | D22: 2675 | E22: 21791 | F22: 83.15 | G22: 47031 | H22: 10071 | I22: 721000 | J22: 7.86 | K22: Australia | M22: 1.39681 | N22: 6.5230236 | O22: 115.32594 | P22: 721000 | Q22: High | R22: Moderate (6-8%)
A23: 2021 | B23: Australia | C23: Oceania | D23: 3167 | E23: 24324 | F23: 89.38 | G23: 200325 | H23: 18717 | J23: 6.38 | K23: Australia | P23: 721000 | Q23: Normal | R23: Moderate (6-8%)
A24: 2022 | B24: Australia | C24: Oceania | D24: 3346 | E24: 41145 | F24: 111.22 | G24: 357038 | H24: 27402 | J24: 4.82 | K24: Australia | P24: 721000 | Q24: Normal | R24: Low (<6%)
A25: 2023 | B25: Australia | C25: Oceania | D25: 3638 | F25: 119.53 | G25: 287259 | J25: 4.17 | K25: Australia | Q25: Normal | R25: Low (<6%)
A26: 2024 | B26: Australia | C26: Oceania | D26: 3910 | F26: 137.67 | G26: 302758 | I26: 916000 | J26: 4.17 | K26: Australia | N26: 33.052183 | O26: 150.29476 | P26: 916000 | Q26: High | R26: Low (<6%)
A27: 2025 | B27: Australia | C27: Oceania | J27: 4.22 | K27: Australia | P27: 916000 | Q27: Normal | R27: Low (<6%)
A28: 2000 | B28: Canada | C28: North America | D28: 468.4 | E28: 26122 | F28: 12.88 | I28: 217000 | J28: 7.62 | K28: Canada | O28: 59.354839 | P28: 217000 | Q28: Normal | R28: Moderate (6-8%)
A29: 2001 | B29: Canada | C29: North America | D29: 485.44 | F29: 14.27 | J29: 7.61 | K29: Canada | P29: 217000 | Q29: Normal | R29: Moderate (6-8%)
A30: 2002 | B30: Canada | C30: North America | D30: 514.94 | F30: 15.74 | J30: 7.68 | K30: Canada | P30: 217000 | Q30: Normal | R30: Moderate (6-8%)
A31: 2003 | B31: Canada | C31: North America | D31: 607.7 | F31: 21 | J31: 7.63 | K31: Canada | Q31: Normal | R31: Moderate (6-8%)
A32: 2004 | B32: Canada | C32: North America | D32: 709.15 | F32: 18.75 | J32: 7.6 | K32: Canada | Q32: Normal | R32: Moderate (6-8%)
A33: 2005 | B33: Canada | C33: North America | D33: 820.38 | F33: 22.13 | J33: 7.55 | K33: Canada | Q33: Normal | R33: Moderate (6-8%)
A34: 2006 | B34: Canada | C34: North America | D34: 940.26 | F34: 28.33 | J34: 7.55 | K34: Canada | Q34: Normal | R34: Moderate (6-8%)
A35: 2007 | B35: Canada | C35: North America | D35: 1217 | F35: 37.22 | J35: 7.56 | K35: Canada | Q35: Normal | R35: Moderate (6-8%)
A36: 2008 | B36: Canada | C36: North America | D36: 1199 | F36: 49.98 | J36: 7.63 | K36: Canada | Q36: Normal | R36: Moderate (6-8%)
A37: 2009 | B37: Canada | C37: North America | D37: 1342 | F37: 49.2 | J37: 7.64 | K37: Canada | Q37: Normal | R37: Moderate (6-8%)
A38: 2010 | B38: Canada | C38: North America | D38: 1676 | E38: 30311 | F38: 53.48 | I38: 540000 | J38: 7.63 | K38: Canada | O38: 99.037037 | P38: 540000 | Q38: Normal | R38: Moderate (6-8%)
A39: 2011 | B39: Canada | C39: North America | D39: 1823 | F39: 62.5 | J39: 7.61 | K39: Canada | P39: 540000 | Q39: Normal | R39: Moderate (6-8%)
A40: 2012 | B40: Canada | C40: North America | D40: 1828 | F40: 68.82 | J40: 7.64 | K40: Canada | P40: 540000 | Q40: Normal | R40: Moderate (6-8%)
...

Sheet Executive Insights
B2: Executive Insights
B3: 10 evidence-based findings, each with business impact and a recommendation.
B5: Insight | C5: What Happened | D5: Business Impact | E5: Recommendation
B6: 1. UAE is the largest single destination for Indian migrants | C6: As of 2024, the UAE hosts an estimated 3.25 million Indian migrants, the highest of the 7 countries tracked, narrowly ahead of the USA (3.17 million). | D6: The UAE corridor is disproportionately important to remittance flows and household income support in source states. | E6: Prioritize worker-protection agreements and skill-certification programs with the UAE given the scale of exposure.
B7: 2. Canada shows the fastest proportional growth of any tracked destination | C7: Canada's Indian migrant stock grew from 217,000 (2000) to 1.28 million (2024), a ~490% increase, the highest growth rate among all 7 countries. | D7: Canada has shifted from a minor destination to a top-3 corridor in two decades, driven by its points-based PR system and post-study work rights. | E7: Scale Canada-specific settlement and financial-literacy programs to match this growth.
B8: 3. The UK is the slowest-growing major destination | C8: UK migrant stock grew only ~70% between 2000 and 2024 (570,000 -> 970,000), far below every other tracked country. | D8: The UK's share of the total tracked Indian diaspora is shrinking relative to Canada, Australia, and the UAE, likely reflecting post-Brexit visa tightening. | E8: Flag the UK's comparatively constrained growth trajectory to prospective migrants against faster-expanding alternatives.
B9: 4. India's GDP grew 8.3x, but this coincided with rising, not falling, emigration | C9: India's GDP rose from $468B (2000) to $3.91T (2024) while migrant stock to these 7 destinations also rose sharply over the same period. | D9: Rising GDP alone is not a reliable predictor of reduced outward migration in this dataset - consistent with the globally observed 'migration hump.' | E9: Revisit policy framing that assumes GDP growth will organically curb migration.
B10: 5. Remittances grew over 10x, closely tracking GDP, not migrant headcount | C10: Remittances rose from $12.9B (2000) to $137.7B (2024), a ~10.7x increase, correlating strongly with India's GDP (r=0.98) and negatively with unemployment (r=-0.75). | D10: Remittance inflows are a resilient, expanding pillar of India's external finances, effectively decoupled from domestic unemployment cycles. | E10: Treat remittances as a structurally growing revenue stream; keep investing in low-cost remittance-channel infrastructure.
B11: 6. India's unemployment has been comparatively stable, with a 2020 spike and 2023 low | C11: Unemployment ranged narrowly between ~4.2% and ~7.9% across 2000-2024, spiking to 7.86% in 2020 and falling to a period-low 4.17% in 2023. | D11: Despite the 2020 shock, unemployment does not show a long-run deteriorating pattern over the 25-year window. | E11: Monitor the 2023 low for durability before treating it as a structural improvement.
B12: 7. UAE and Australia are the only countries where migrant stock declined between benchmarks | C12: The UAE's stock fell from 3.5M (2020) to 3.25M (2024), a rare contraction among tracked destinations. | D12: The UAE, while still the largest single destination, is the only tracked market showing net contraction risk, possibly tied to COVID-era return migration or labor localization policy. | E12: Treat the UAE corridor as maturing/plateauing rather than assuming continued high growth.
B13: 8. Workforce vs. student composition data is too sparse to generalize | C13: Only 2 of 182 country-year records have both Temporary Worker Share and Student Share populated (Australia 2020, UK 2024). | D13: Any dashboard claiming to show 'workforce vs. student migration trends' across all 7 countries would be showing mostly gaps, not signal. | E13: Flag this explicitly in any report using these fields; treat the 2 data points as anecdotes, not a trend.
B14: 9. GDP and Unemployment fields are national, not country-specific | C14: GDP_India and Unemployment_India repeat the same value across all 7 destination countries for a given year. | D14: Any correlation between these fields and a specific country's migrant stock reflects India-side conditions, not destination-country demand. | E14: Label these fields explicitly as 'India national indicator' to avoid misinterpretation.
B15: 10. Data completeness itself is a finding: 53% of raw cells are 'NOT AVAILABLE' | C15: Of 1,323 raw data cells, 703 (53.1%) are explicitly marked unavailable, concentrated in Permanent Migrants, Temporary Workers, and Students for most years. | D15: Any executive dashboard should surface data-completeness context rather than implying full annual coverage. | E15: Prioritize follow-up data sourcing for these sub-metrics if strategically important.

Sheet Data Quality Report
B2: Data Quality Report
B4: Issues Found (Before Cleaning)
B5: Source | C5: Raw_Data/indian_overseas_migration_dataset.csv - long format, one row per (Year, Destination Country, Metric).
B6: Total raw rows | C6: 1,323
B7: Exact duplicate rows | C7: 0
B8: Cells marked NOT AVAILABLE | C8: 703 (53.1% of all cells)
B9: Rows missing a cited source | C9: 703
B10: Mixed value formats found | C10: Plain numbers, percentages, and currency strings ($468.40B and $1.217T) all stored as text in one column.
B11: Reshape required | C11: Data was long-format (one metric per row); pivoted to one row per Year x Country for analysis.
B13: Missing Values After Reshaping (per column)
B14: Column | C14: Missing Count | D14: Missing %
B15: Year | C15: 0 | D15: 0.0%
B16: Destination Country | C16: 0 | D16: 0.0%
B17: Region | C17: 0 | D17: 0.0%
B18: GDP India USD Billion | C18: 7 | D18: 3.8%
B19: Permanent Migrants | C19: 164 | D19: 90.1%
B20: Remittance USD Billion | C20: 7 | D20: 3.8%
B21: Students | C21: 159 | D21: 87.4%
B22: Temporary Workers | C22: 170 | D22: 93.4%
B23: Total Indian Migrants | C23: 147 | D23: 80.8%
B24: Unemployment India | C24: 0 | D24: 0.0%
B25: Destination Country Full | C25: 0 | D25: 0.0%
B26: Migrant YoY Growth Pct | C26: 182 | D26: 100.0%
... B32: India Unemployment Category | C32: 0 | D32: 0.0%
B34: Key Data Limitations
B35: - Scope: only 7 destination countries are covered - a sample of major corridors, not a complete global picture.
B36: - Granularity: no Indian state-level, gender, age, or education breakdown exists in the source file.
B37: - Migrant-count data (Permanent/Temporary/Students) is sparse, especially pre-2010.
B38: - GDP_India and Unemployment_India are national figures, repeated across all 7 countries per year.
B39: - Years extend to 2026; the most recent 1-2 years may be projections rather than finalized statistics.

Sheet Data Dictionary
B2: Data Dictionary
B4: Column | C4: Description | D4: Source Coverage
B5: Year | C5: Calendar year of the record | D5: Full, 2000-2026
B6: Destination Country | C6: Short country name | D6: Full
B7: Destination Country Full | C7: Standardized full country name | D7: Full
B8: Region | C8: Geographic region of destination country | D8: Full
B9: Total Indian Migrants | C9: Estimated total stock of Indian-born migrants in that country | D9: Sparse - benchmark years only (2000, 2005/2010, 2015, 2020, 2024)
B10: Permanent Migrants | C10: Estimated permanent-resident migrants | D10: Very sparse
B11: Temporary Workers | C11: Estimated temporary/contract workers | D11: Very sparse
B12: Students | C12: Estimated Indian student population | D12: Very sparse
B13: Remittance USD Billion | C13: India-WIDE total remittances received (not country-specific) | D13: Near-full, 2000-2024
B14: Unemployment India | C14: India-WIDE national unemployment rate (%) | D14: Full
B15: GDP India USD Billion | C15: India-WIDE GDP in USD billions (normalized from mixed $B/$T source notation) | D15: Near-full, 2000-2024; 2025-2026 not yet available
... B22: India Unemployment Category | C22: Bucketed unemployment rate: Low (<6%), Moderate (6-8%), High (>8%) | D22: Derived
B25: Important Interpretation Notes
B26: - Remittance, Unemployment, and GDP fields are national (India-wide) figures, repeated identically across all 7 destination countries for a given year. Never sum them across countries.
B27: - Total Indian Migrants and its sub-categories are only available for benchmark years - any year-over-year growth spans multi-year gaps, not annual change.
B28: - All currency figures are normalized to USD Billions (source mixed $B and $T notation).
